// posit_48_2.cpp: test suite runner for specialized extended standard 48-bit posit<48,2>
//
// Copyright (C) 2017-2021 Stillwater Supercomputing, Inc.
//
// This file is part of the universal numbers project, which is released under an MIT Open Source license.
#if defined(_MSC_VER)
#pragma warning(disable : 5045) // Compiler will insert Spectre mitigation for memory load if /Qspectre switch specified
#pragma warning(disable : 4514) // unreferenced inline function has been removed
#pragma warning(disable : 4820) // bytes padding added after data member
#pragma warning(disable : 4710) // function not inlined
#endif
// Configure the posit template environment
// first: enable fast specialized posit<48,2>
#define POSIT_FAST_POSIT_48_2 1    // TODO: fast posit<48,2> not implemented yet
// second: enable posit arithmetic exceptions
#define POSIT_THROW_ARITHMETIC_EXCEPTION 1
#include <universal/number/posit/posit.hpp>
#include <universal/verification/posit_test_suite.hpp>
#include <universal/verification/posit_test_randoms.hpp>

/*
Extended Standard posit with nbits = 48 have es = 2 exponent bits.
*/

#define STRESS_TESTING 1

int main()
try {
	using namespace sw::universal;

	constexpr size_t RND_TEST_CASES = 10000;

	constexpr size_t nbits = 48;
	constexpr size_t es = 2;

	int nrOfFailedTestCases = 0;
	bool bReportIndividualTestCases = false;
	std::string tag = " posit<48,2>";

#if POSIT_FAST_POSIT_48_2
	std::cout << "Fast specialization posit<48,2> configuration tests\n";
#else
	std::cout << "Extended Standard posit<48,2> configuration tests\n";
#endif

	posit<nbits, es> p;
	std::cout << dynamic_range(p) << "\n\n";

	// special cases
	std::cout << "Special case tests\n";
	std::string test = "Initialize to zero: ";
	p = 0;
	nrOfFailedTestCases += ReportCheck(tag, test, p.iszero());
	test = "Initialize to NAN";
	p = NAN;
	nrOfFailedTestCases += ReportCheck(tag, test, p.isnar());
	test = "Initialize to INFINITY";
	p = INFINITY;
	nrOfFailedTestCases += ReportCheck(tag, test, p.isnar());
	test = "sign is true";
	p = -1.0f;
	nrOfFailedTestCases += ReportCheck(tag, test, p.sign());
	test = "is negative";
	nrOfFailedTestCases += ReportCheck(tag, test, p.isneg());
	test = "sign is false";
	p = +1.0f;
	nrOfFailedTestCases += ReportCheck(tag, test, !p.sign());
	test = "is positive";
	nrOfFailedTestCases += ReportCheck(tag, test, p.ispos());

	// TODO: as we don't have a reference floating point implementation to Verify
	// the arithmetic operations we are going to ignore the failures
#if STRESS_TESTING
	std::cout << "Arithmetic tests " << RND_TEST_CASES << " randoms each\n";
	std::cout << "Without an arithmetic reference, test failures can be ignored\n";
	nrOfFailedTestCases += ReportTestResult(VerifyBinaryOperatorThroughRandoms<nbits, es>(bReportIndividualTestCases, OPCODE_ADD, RND_TEST_CASES), tag, "addition      ");
	nrOfFailedTestCases += ReportTestResult(VerifyBinaryOperatorThroughRandoms<nbits, es>(bReportIndividualTestCases, OPCODE_SUB, RND_TEST_CASES), tag, "subtraction   ");
	nrOfFailedTestCases += ReportTestResult(VerifyBinaryOperatorThroughRandoms<nbits, es>(bReportIndividualTestCases, OPCODE_MUL, RND_TEST_CASES), tag, "multiplication");
	nrOfFailedTestCases += ReportTestResult(VerifyBinaryOperatorThroughRandoms<nbits, es>(bReportIndividualTestCases, OPCODE_DIV, RND_TEST_CASES), tag, "division      ");
#endif
	nrOfFailedTestCases = 0;
	return (nrOfFailedTestCases > 0 ? EXIT_FAILURE : EXIT_SUCCESS);
}
catch (char const* msg) {
	std::cerr << msg << std::endl;
	return EXIT_FAILURE;
}
catch (const sw::universal::posit_arithmetic_exception& err) {
	std::cerr << "Uncaught posit arithmetic exception: " << err.what() << std::endl;
	return EXIT_FAILURE;
}
catch (const sw::universal::quire_exception& err) {
	std::cerr << "Uncaught quire exception: " << err.what() << std::endl;
	return EXIT_FAILURE;
}
catch (const sw::universal::posit_internal_exception& err) {
	std::cerr << "Uncaught posit internal exception: " << err.what() << std::endl;
	return EXIT_FAILURE;
}
catch (const std::runtime_error& err) {
	std::cerr << "Uncaught runtime exception: " << err.what() << std::endl;
	return EXIT_FAILURE;
}
catch (...) {
	std::cerr << "Caught unknown exception" << std::endl;
	return EXIT_FAILURE;
}

