// add.cpp: functional tests for addition on adaptive precision binary integer
//
// Copyright (C) 2017-2021 Stillwater Supercomputing, Inc.
//
// This file is part of the universal numbers project, which is released under an MIT Open Source license.
#include <iostream>
#include <iomanip>
#include <string>
#include <cmath>
#include <limits>

// minimum set of include files to reflect source code dependencies
#include <universal/adaptiveint/adaptiveint.hpp>
#include <universal/verification/test_status.hpp> // ReportTestResult

// generate specific test case that you can trace with the trace conditions in mpreal.hpp
// for most bugs they are traceable with _trace_conversion and _trace_add
template<typename Ty>
void GenerateTestCase(Ty _a, Ty _b) {
	Ty ref;
	sw::universal::adaptiveint a, b, aref, asum;
	a = _a;
	b = _b;
	asum = a + b;
	ref = _a + _b;
	aref = ref;
	constexpr size_t ndigits = 30;
	std::cout << std::setw(ndigits) << _a << " + " << std::setw(ndigits) << _b << " = " << std::setw(ndigits) << ref << std::endl;
	std::cout << a << " + " << b << " = " << asum << " (reference: " << aref << ")   " ;
	std::cout << (aref == asum ? "PASS" : "FAIL") << std::endl << std::endl;
}

#define MANUAL_TESTING 1
#define STRESS_TESTING 0

int main(int argc, char** argv)
try {
	using namespace std;
	using namespace sw::universal;

	int nrOfFailedTestCases = 0;

	std::string tag = "adaptive precision binary integer addition failed: ";

#if MANUAL_TESTING
//	bool bReportIndividualTestCases = false;

	// generate individual testcases to hand trace/debug
	GenerateTestCase(1, 2);

#else

	cout << "adaptive precision linear float addition validation" << endl;


#if STRESS_TESTING

#endif  // STRESS_TESTING

#endif  // MANUAL_TESTING

	return (nrOfFailedTestCases > 0 ? EXIT_FAILURE : EXIT_SUCCESS);
}
catch (char const* msg) {
	std::cerr << msg << std::endl;
	return EXIT_FAILURE;
}
catch (const std::runtime_error& err) {
	std::cerr << "Uncaught runtime exception: " << err.what() << std::endl;
	return EXIT_FAILURE;
}
catch (...) {
	std::cerr << "Caught unknown exception" << std::endl;
	return EXIT_FAILURE;
}
